Workbook

Sheet Presumido Industrialização
G4: Precificação por Margem de Contribuição Presumido
I8: Matéria Prima | Fornecedores | Insumos
C10: Base para formação do preço de venda
C11: Produto | F11: Base bruta com valores/créditos recuperáveis (Exceto CBS e IBS) | I11: Produto | N11: Valores com ICMS e PIS/COFINS por dentro | Q11: Produto | U11: Valores com ICMS e PIS/COFINS por dentro | W11: Produto | AB11: Valores com ICMS e PIS/COFINS por dentro
C12: Total materiais | F12: =N12+U12+AB12 -> 1140000 | I12: PVC | N12: 800000 | Q12: Ferragens | U12: 300000 | W12: Frete | AB12: 40000
C14: IPI Custo (Quando não gera crédito) | F14: =N14+U14+AB14 -> 80000 | I14: IPI Custo (Quando não gera crédito) | N14: 80000 | Q14: IPI Custo (Quando não gera crédito) | W14: IPI Custo (Quando não gera crédito)
C15: ICMS-ST /DIFAL (Quando não gera crédito) | F15: =N15+U15+AB15 -> 150000 | I15: ICMS-ST / DIFAL (Quando não gera crédito) | N15: 150000 | Q15: ICMS-ST / DIFAL (Quando não gera crédito) | W15: ICMS-ST (Quando não gera crédito)
C16: CNAE defini se o IPI será crédito ou custo | I16: NCM/CNAE defini se será crédito ou custo | Q16: NCM/CNAE defini se será crédito ou custo | W16: NCM/CNAE defini se será crédito ou custo
C19: Valor total custo MP/Fornecedores | F19: =SUM(F12:G15)-SUM(F17:G17) -> 1370000 | I19: Custo líquido do produto | N19: =N12+N14+N15-SUM(N17:O17) -> 1030000 | Q19: Custo líquido do produto | U19: =SUM(U12+U14+U15-SUM(U17:U17)) -> 300000 | W19: Custo líquido do produto | AB19: =SUM(AB12+AB14+AB15-SUM(AB17:AC17)) -> 40000
I24: Mão de Obra Produtiva Propria | Terceirizada
C26: Base para formação do preço de venda
I27: Mão de Obra Direta (Produtiva) | N27: Valor da MO (Bruta) | Q27: Mão de Obra Direta (Produtiva) | U27: Valor da MO (Bruta)
C28: Valor total da mão de obra | F28: =SUM(N28,U28) -> 250000 | I28: Mão de Obra Própria | N28: 250000 | Q28: Mão de Obra Terceirizada
C31: Valor total custo Mâo Obra | F31: =SUM(F28) -> 250000
C36: Valores oriundos do sistema Precifica Certo
C37: Previsão Mensal | E37: %
B39: =SUM(E39:E41) -> 0.5523 | C39: Custo Produtos | E39: =O39 -> 0.46706852 | O39: =U39/U65 -> 0.46706852 | P39: Custo de Obra / Materiais | U39: =F19 -> 1370000
C40: Custo MO Direta | E40: =O40 -> 0.085231481 | O40: =U40/U65 -> 0.085231481 | P40: Folha de Obra / Empreiteiros | U40: =F31 -> 250000
P42: Coeficiente | Q42: =1-SUM(O43:O62) -> 0.5523 | T42: Total CMV | U42: =SUM(U39:U40) -> 1620000
B45: =SUM(E45:E48) -> 0.2277 | C45: Desp. MO Indireta | E45: 0.0622 | O45: =E45 -> 0.0622 | P45: MO Indireta | U45: =U65*O45 -> 182444.32
C46: Desp. Fixa | E46: 0.1049 | O46: =E46 -> 0.1049 | P46: Fixa | U46: =U65*O46 -> 307691.47
C47: Desp. Variável | E47: 0.06 | O47: =E47 -> 0.06 | P47: Variavel | U47: =U65*O47 -> 175991.31
C48: Desp. Financeira | E48: 0.0006 | O48: =E48 -> 0.0006 | P48: Financeira | U48: =U65*O48 -> 1759.9131
B51: =E52 -> 0.04
C52: Regime tributário (Verificar % especial) | E52: 0.04 | G52: -----> | H52: -----> | I52: -----> | L52: -----> | M52: -----> | O52: =E52 -> 0.04 | P52: RET | U52: =U65*O52 -> 117327.54
B55: =SUM(E56) -> 0.06
C56: Comissões | E56: 0.06 | G56: -----> | H56: -----> | I56: -----> | L56: -----> | M56: -----> | O56: =E56 -> 0.06 | P56: Comissão | U56: =U65*O56 -> 175991.31
B59: =SUM(E60) -> 0.12
C60: Margem de Lucro | E60: 0.12 | G60: -----> | H60: -----> | I60: -----> | L60: -----> | M60: -----> | O60: =E60 -> 0.12 | P60: Lucro Liquido Desejado | U60: =U65*O60 -> 351982.62
O65: =SUM(O39:O62) -> 1 | P65: Valor total da operação interna do preço de venda (Base Líquida da Operação) | U65: =U42/Q42 -> 2933188.5
C70: % Fator de redução da alíquota | G70: Base de Débito IBS respeitando a relação complementar de tributos
G71: Valor da operação interna | L71: =U65 -> 2933188.5
C72: 0
G73: Total "Valor operação interna + IS" | L73: =SUM(L71:L72) -> 2933188.5
C74: Redutor será ativado somente em 2033 no Iva Dual pleno | G74: Alíquota IBS | H74: 0.009 | J74: Alíquota Reduzida | L74: =H74*(1-C72) -> 0.009
G75: Déb sob base complem da receita | J75: (+) | L75: =L73*L74 -> 26398.696 | M75: -----> | P75: IBS a recolher e destacar na nota
D78: Acionador "x" | G78: Base de Débito CBS respeitando a relação complementar de tributos
G79: Valor da operação interna | L79: =U65 -> 2933188.5
D80: x
G81: Total "Valor operação interna + IS" | L81: =SUM(L79:L80) -> 2933188.5
...

Sheet Categorias
C3: Total % | D3: Custo dos produtos | E3: FORNECEDORES - Produtos para Revenda
E4: MATÉRIA PRIMA - Base dos prod.
E5: EMBALAGENs INDIVIDUAIS
E6: FRETES FOB (Valores relacionados a compra de suprimentos)
C20: Total % | D20: Custo Mão de obra Produção | E20: SALÁRIOS PRODUÇÃO
E21: DÉCIMO TERCEIRO (Setor Produtivo)
E22: FÉRIAS COLABORADORES (Setor produtivo)
E23: FGTS (Setor Produtivo)
E24: HORAS EXTRAS - SALÁRIOS
E25: INSS (Setor Produtivo)
E26: INSS PATRONAL (Setor Produtivo)
E27: PLANO DE SAÚDE (Setor Produtivo)
E28: RAT / FAP
E29: VALE ALIMENTAÇÃO (Setor Produtivo)
E30: VALE TRANSPORTE (Setor Produtivo)
E31: MÃO DE OBRA PRODUTIVA TERCEIRIZADA - Passivel de crédito
C35: Total % | D35: Despesa Mão de obra Indireta | E35: PRÓ LABORE
E36: SALÁRIOS ADMINISTRATIVOS
E37: SALÁRIOS COMERCIAIS
E38: DÉCIMO TERCEIRO (Pró-Labo/ Admin/ Comer)
E39: FÉRIAS COLABORADORES (Pró-Labo/ Admin/ Comer)
E40: FGTS (Pró-Labo/ Admin/ Comer)
E41: HORAS EXTRAS - SALÁRIOS
E42: INSS PATRONAL (Pró-Labo/ Admin/ Comer)
E43: INSS (Pró-Labo/ Admin/ Comer)
E44: PLANO DE SAÚDE (Pró-Labo/ Admin/ Comer)
E45: RAT / FAP
E46: VALE ALIMENTAÇÃO (Pró-Labo/ Admin/ Comer)
E47: VALE TRANSPORTE (Pró-Labo/ Admin/ Comer)
C51: Total % | D51: Despesas fixas | E51: ÁGUA
E52: ALUGUEL
E53: APLICAÇÕES/CONSÓRCIOS
E54: CONSULTORIA
E55: CONTABILIDADE
E56: DEPRECIAÇÃO
E57: EMPRÉSTIMOS / FINANCIAMENTOS
E58: ENERGIA ELÉTRICA
E59: IMPOSTOS IPTU / IPVA
E60: INTERNET
E61: SEGURANÇA / MONITORAMENTO
...

Sheet DRE Financeiro
C3: DRE - Financeiro
C4: Demonstrativo do Resultado do Exercício
D6: Receita Bruta | J6: ='Presumido Industrialização'!U88 -> 2933188.5
H7: Valores oriundos da base Anual
C8: (-) | D8: Deduções Tributárias Sobre Receita | J8: =SUM(H9:H9) -> 0
D9: Impostos sobre faturamento | H9: ='Presumido Industrialização'!U88-'Presumido Industrialização'!U65 -> 0
C11: = | D11: Receita líquida de venda interna | J11: =J6-J8 -> 2933188.5 | N11: 1
C13: (-) | D13: Deduções Tributárias Faturamento | J13: =SUM(H14:H18) -> 1737327.5 | L13: =J13/$J$11 -> 0.5923
D14: RET - Impostos sobre faturamento | G14: =H14/J11 -> 0.04 | H14: ='Presumido Industrialização'!U52 -> 117327.54
C16: (-) | D16: Custos Líquido dos Produtos (Base operacional - CMV)
D17: Custo Líquido dos Produtos | G17: =H17/$J$11 -> 0.46706852 | H17: ='Presumido Industrialização'!U39 -> 1370000
D18: Folha de Obra / Empreiteiros | G18: =H18/$J$11 -> 0.085231481 | H18: ='Presumido Industrialização'!U40 -> 250000
C20: = | D20: Lucro Bruto | J20: =J11-J13 -> 1195860.9 | N20: =N11-L13 -> 0.4077
C22: (-) | D22: Despesas Operacionais | J22: =SUM(H23:H26) -> 842118.41 | L22: =J22/$J$11 -> 0.2871
D23: Despesa MO Indireta | G23: =H23/$J$11 -> 0.0622 | H23: ='Presumido Industrialização'!U45 -> 182444.32
D24: Despesa Fixa | G24: =H24/$J$11 -> 0.1049 | H24: ='Presumido Industrialização'!U46 -> 307691.47
D25: Despesa Variavel | G25: =H25/$J$11 -> 0.06 | H25: ='Presumido Industrialização'!U47 -> 175991.31
D26: Comissões | G26: =H26/$J$11 -> 0.06 | H26: ='Presumido Industrialização'!U56 -> 175991.31
C28: = | D28: Lucro Operacional (EBITA/EBIT) | J28: =J20-J22 -> 353742.53 | N28: =N20-L22 -> 0.1206
C30: (-) | D30: Despesas Financeiras | J30: =H31 -> 1759.9131 | L30: =J30/$J$11 -> 0.0006
D31: Despesa Financeira | G31: =H31/J11 -> 0.0006 | H31: ='Presumido Industrialização'!U48 -> 1759.9131
C33: = | D33: Resultado Financeiro | J33: =J28-J30 -> 351982.62 | N33: =N28-L30 -> 0.12
H35: Lucro Líquido | J35: =J33 -> 351982.62 | N35: =J35/J11 -> 0.12
