Workbook

Sheet Simples Revenda
G4: Precificação por Margem de Contribuição Simples
I8: Matéria Prima | Fornecedores | Insumos
C10: Base para formação do preço de venda
C11: Produto | F11: Base bruta com valores/créditos recuperáveis (Exceto CBS e IBS) | I11: Produto | N11: Base bruta com valores calculados por dentro (Exceto IPI | CBS e IBS) | Q11: Produto | U11: Base bruta com valores calculados por dentro (Exceto IPI | CBS e IBS) | W11: Produto | AB11: Base bruta com valores calculados por dentro (Exceto IPI | CBS e IBS)
C12: Total materiais | F12: =N12+U12+AB12 -> 1140000 | I12: PVC | N12: 800000 | Q12: Ferragens | U12: 300000 | W12: Frete | AB12: 40000
C13: IPI Custo (Quando não gera crédito) | F13: =N13+U13+AB13 -> 80000 | I13: IPI Custo (Quando não gera crédito) | N13: 80000 | Q13: IPI Custo (Quando não gera crédito) | W13: IPI Custo (Quando não gera crédito)
C14: ICMS-ST (Quando não gera crédito) | F14: =N14+U14+AB14 -> 150000 | I14: ICMS-ST (Quando não gera crédito) | N14: 150000 | Q14: ICMS-ST (Quando não gera crédito) | W14: ICMS-ST (Quando não gera crédito)
C15: NCM/CNAE defini se será crédito ou custo | I15: NCM/CNAE defini se será crédito ou custo | Q15: NCM/CNAE defini se será crédito ou custo | W15: NCM/CNAE defini se será crédito ou custo
C18: Valor total custo MP/Fornecedores | F18: =SUM(F12:G14)-SUM(F16:G16) -> 1370000 | I18: Custo líquido do produto | N18: =N12+N13+N14-SUM(N16:O16) -> 1030000 | Q18: Custo líquido do produto | U18: =SUM(U12+U13+U14-SUM(U16:U16)) -> 300000 | W18: Custo líquido do produto | AB18: =SUM(AB12+AB13+AB14-SUM(AB16:AC16)) -> 40000
C24: Valores oriundos do sistema Precifica Certo
C25: Previsão Mensal | E25: %
B26: =SUM(E27:E28) -> 0.5123
C27: Custo Produtos | E27: =O27 -> 0.5123 | O27: =U27/U52 -> 0.5123 | P27: Custo Total dos Produtos | U27: =F18 -> 1370000
P29: Coeficiente | Q29: =1-SUM(O30:O49) -> 0.5123 | T29: Total CMV | U29: =SUM(U27:U27) -> 1370000
B32: =SUM(E32:E35) -> 0.2277 | C32: Desp. MO Total | E32: 0.0622 | O32: =E32 -> 0.0622 | P32: MO Direta + Indireta | U32: =U52*O32 -> 166336.13
C33: Desp. Fixa | E33: 0.1049 | O33: =E33 -> 0.1049 | P33: Fixa | U33: =U52*O33 -> 280525.08
C34: Desp. Variável | E34: 0.06 | O34: =E34 -> 0.06 | P34: Variavel | U34: =U52*O34 -> 160452.86
C35: Desp. Financeira | E35: 0.0006 | O35: =E35 -> 0.0006 | P35: Financeira | U35: =U52*O35 -> 1604.5286
B38: =SUM(E39) -> 0.08
C39: Simples | E39: 0.08 | G39: -----> | H39: -----> | I39: -----> | L39: -----> | M39: -----> | O39: =E39 -> 0.08 | P39: Simples Nacional | U39: =U52*O39 -> 213937.15
B42: =SUM(E43) -> 0.06
C43: Comissões | E43: 0.06 | G43: -----> | H43: -----> | I43: -----> | L43: -----> | M43: -----> | O43: =E43 -> 0.06 | P43: Comissão | U43: =U52*O43 -> 160452.86
B46: =SUM(E47) -> 0.12
C47: Margem de Lucro | E47: 0.12 | G47: -----> | H47: -----> | I47: -----> | L47: -----> | M47: -----> | O47: =E47 -> 0.12 | P47: Lucro Liquido Desejado | U47: =U52*O47 -> 320905.72
O52: =SUM(O27:O49) -> 1 | P52: Valor da operação interna | U52: =U29/Q29 -> 2674214.3
P55: Frete | U55: 0
P57: Seguros | U57: 0
P59: Despesas Acessórias | U59: 0
N62: Valor total da operação interna do preço de venda (Base Líquida da Operação) | U62: =SUM(U52:U59) -> 2674214.3
G66: Calculado por fora IS
D67: Acionador "x" | G67: Valor da operação interna de preço | L67: =IF(D69="X", U36, "")
G68: Valor da alíquota de venda | L68: 0.05
G70: Valor de IS a reter | L70: =IF(D69="x",L67*L68,"") | M70: -----> | P70: Total imposto IS a destacar na nota | U70: =L70
G76: ICMS-ST
G79: Cálculo do ICMS-ST
D80: Acionador "x" | G80: Valor da operação interna de preço | L80: =IF(D82="x",U36,"")
G81: Valor do IPI | L81: =IF(D82="x",#REF!,"")
G82: Valor total da base do calculo | L82: =SUM(L80:L81) -> 0
G83: MVA original | L83: 0.4
G84: ICMS interestadual (operação entre estados) | L84: 0.12
...

Sheet Categorias Simples
C3: Total % | D3: Custo dos produtos | E3: FORNECEDORES - Produtos para Revenda
E4: MATÉRIA PRIMA - Base dos prod.
E5: EMBALAGENs INDIVIDUAIS
E6: FRETES FOB (Valores relacionados a compra de suprimentos)
C10: Total % | D10: Custo Mão de obra Produção | E10: SALÁRIOS PRODUÇÃO
E11: DÉCIMO TERCEIRO (Setor Produtivo)
E12: FÉRIAS COLABORADORES (Setor produtivo)
E13: FGTS (Setor Produtivo)
E14: HORAS EXTRAS - SALÁRIOS
E15: INSS (Setor Produtivo)
E16: INSS PATRONAL (Setor Produtivo)
E17: PLANO DE SAÚDE (Setor Produtivo)
E18: RAT / FAP
E19: VALE ALIMENTAÇÃO (Setor Produtivo)
E20: VALE TRANSPORTE (Setor Produtivo)
E21: MÃO DE OBRA PRODUTIVA TERCEIRIZADA - Passivel de crédito
D22: Despesa Mão de obra Indireta | E22: PRÓ LABORE
E23: SALÁRIOS ADMINISTRATIVOS
E24: SALÁRIOS COMERCIAIS
E25: DÉCIMO TERCEIRO (Pró-Labo/ Admin/ Comer)
E26: FÉRIAS COLABORADORES (Pró-Labo/ Admin/ Comer)
E27: FGTS (Pró-Labo/ Admin/ Comer)
E28: HORAS EXTRAS - SALÁRIOS
E29: INSS (Pró-Labo/ Admin/ Comer)
E30: INSS PATRONAL (Pró-Labo/ Admin/ Comer)
E31: PLANO DE SAÚDE (Pró-Labo/ Admin/ Comer)
E32: RAT / FAP
E33: VALE ALIMENTAÇÃO (Pró-Labo/ Admin/ Comer)
E34: VALE TRANSPORTE (Pró-Labo/ Admin/ Comer)
C38: Total % | D38: Despesas fixas | E38: ÁGUA
E39: ALUGUEL
E40: APLICAÇÕES/CONSÓRCIOS
E41: CONSULTORIA
E42: CONTABILIDADE
E43: DEPRECIAÇÃO
E44: EMPRÉSTIMOS / FINANCIAMENTOS
E45: ENERGIA ELÉTRICA
E46: IMPOSTOS IPTU / IPVA
E47: INTERNET
E48: SEGURANÇA / MONITORAMENTO
...

Sheet Simples DRE Financeiro
C3: DRE - Financeiro
C4: Demonstrativo do Resultado do Exercício
D6: Receita Bruta | J6: ='Simples Revenda'!U62 -> 2674214.3
H7: Valores oriundos da base Anual
C8: (-) | D8: Deduções Tributárias Sobre Receita | J8: =SUM(H9:H9) -> 0
D9: Impostos sobre faturamento (Por Fora) | H9: ='Simples Revenda'!U126-'Simples Revenda'!U62 -> 0
D10: Atividades operacionais de entrega | H10: ='Simples Revenda'!U62-'Simples Revenda'!U52 -> 0
C12: = | D12: Receita líquida de venda interna | J12: =J6-J8 -> 2674214.3 | N12: 1
C14: (-) | D14: Deduções Tributárias Sobre Receita | J14: =SUM(H15:H15) -> 213937.15 | L14: =J14/$J$12 -> 0.08
D15: Impostos sobre faturamento | H15: ='Simples Revenda'!U39 -> 213937.15
C18: (-) | D18: Custos Líquido dos Produtos (Base operacional - CMV) | J18: =SUM(H19:H19) -> 1370000 | L18: =J18/$J$12 -> 0.5123
D19: Custo Líquido dos Produtos | G19: =H19/$J$12 -> 0.5123 | H19: ='Simples Revenda'!U27 -> 1370000
C21: = | D21: Lucro Bruto | J21: =J12-J18-J14 -> 1090277.2 | N21: =N12-L18-L14 -> 0.4077
C23: (-) | D23: Despesas Operacionais | J23: =SUM(H24:H27) -> 767766.93 | L23: =J23/$J$12 -> 0.2871
D24: Despesa MO Indireta | G24: =H24/$J$12 -> 0.0622 | H24: ='Simples Revenda'!U32 -> 166336.13
D25: Despesa Fixa | G25: =H25/$J$12 -> 0.1049 | H25: ='Simples Revenda'!U33 -> 280525.08
D26: Despesa Variavel | G26: =H26/$J$12 -> 0.06 | H26: ='Simples Revenda'!U34 -> 160452.86
D27: Comissões | G27: =H27/$J$12 -> 0.06 | H27: ='Simples Revenda'!U43 -> 160452.86
C29: = | D29: Lucro Operacional (EBITA/EBIT) | J29: =J21-J23 -> 322510.25 | N29: =N21-L23 -> 0.1206
C31: (-) | D31: Despesas Financeiras | J31: =H32 -> 1604.5286 | L31: =J31/$J$12 -> 0.0006
D32: Despesa Financeira | G32: =H32/J12 -> 0.0006 | H32: ='Simples Revenda'!U35 -> 1604.5286
H37: Lucro Líquido | J37: =J29-J31 -> 320905.72 | N37: =N29-L31 -> 0.12
